---
title: Promise详解
categories: 
  - 前端面试
tags: 
  - 前端
  - JavaScript
  - Promise
date: 2023-03-28 13:39:15
index_img: /img/article/javascript.png
permalink: /pages/98b0c5/
author: 
  name: 爱写bug的小邓程序员
  link: https://github.com/dengerpu
---

## Promise

> 解决回调地狱问题

当我们`new`一个`promise`，此时我们需要传递一个回调函数，这个函数为立即执行的，称之为（executor）

这个回调函数，我们需要传入两个参数回调函数，`reslove`,`reject`(函数可以进行传参)

- 当执行了`reslove`函数，会回调promise对象的.then函数
- 当执行了`reject`函数，会回调promise对象的.catche函数

### Executor立即执行

```java
new Promise((resolve, reject) => {
    console.log("我是executor函数里面的内容， 我是会立即执行")
    resolve(); // 这里如果不调用， .then里面的函数不会执行  reject()同理
}).then( () => {
    console.log("调用了resolve方法")
}).catch( () => {
    console.log("调用reject方法")
}) 
```

![image-20230328162439999](https://trpora-1300527744.cos.ap-chongqing.myqcloud.com/img/202303281624146.png)

### Promise状态

使用`promise`的时候，给它一个承诺，我们可以将他划分为三个阶段

- pending(待定)，执行了executor，状态还在等待中，没有被兑现，也没有被拒绝
- fulfilled(已兑现)，执行了`resolve`函数则代表了已兑现状态
- rejected(已拒绝)，执行了`reject`函数则代表了已拒绝状态

首先，状态只要**从待定状态，变为其他状态，则状态不能再改变**

```javascript
new Promise((resolve, reject) => {
    reject(); // 两个都调用只会执行一个，因为Promise已经改变
    reject(); // 即使调用两次相同的函数，也只会执行一次
    resolve(); 
}).then( () => {
    console.log("调用了resolve方法")
}).catch( () => {
    console.log("调用reject方法")
}) 

// 调用reject方法
```

- 当我调用`reject`之后，在调用`resolve`是无效的，因为状态已经发生改变，并且是不可逆的。

### resolve不同值的区别

- 如果`resolve`传入一个普通的值或者对象，**只能传递接受一个参数**，那么这个值会作为`then`回调的参数

  ```javascript
  new Promise((resolve, reject) => {
      resolve({name: '张三', age: 5})
  }).then(res => {
      console.log(res);
  })
  // {name: '张三', age: 5}
  ```

- 如果`resolve`中传入的是另外一个`Promise`，那么这个新`Promise`会决定原`Promise`的状态

  ```javascript
  const promise = new Promise((resolve, reject) => {
    resolve(new Promise((resolve, reject) => {
      setTimeout(() => {
        reject('执行失败')
      }, 3000);
    }))
  })
  
  promise.then(res => console.log(res))
  .catch(err => console.log(err))
  
  // 打印内容： 执行失败
  ```

  > 上述例子虽然执行的是resolve,但是会触发传入的Promise的reject,从而执行catch方法。所以**新传入的Promise会决定原来的Promise状态**；

* 如果`resolve`中传入的是一个对象，并且这个对象有实现`then`方法，那么会执行该`then`方法，`then`方法会传入`resolve`，`reject`函数。此时的`promise`状态取决于你调用了`resolve`，还是`reject`函数。这种模式也称之为: **thenable**

  ```javascript
  const promise = new Promise((resolve, reject) => {
    resolve({
      then(res, rej) {
        rej("失败")
      }
    })
  })
  
  promise.then(res => console.log(res))
  .catch(err => console.log(err))
  
  // 输出内容：失败
  ```

### Promise的实例方法

* 实例方法，存放在`Promise.prototype`上的方法，也就是Promise的显示原型上，当我new Promise的时候，会把返回的改对象的 promise[[prototype]]（隐式原型） === Promise.prototype (显示原型)

* 即new返回的对象的隐式原型指向了Promise的显示原型

#### then方法

* `then`方法可以接受参数，一个参数为成功的回调，另一个参数为失败的回调

  ```javascript
  const promise = new Promise((resolve, reject) => {
    // resolve('request success')
    reject('request error')
  })
  
  promise.then(res => console.log(res), rej => console.log(rej))
  
  // 输出内容：request error
  ```

* 如果只捕获错误，还可以这样写

  - 因为第二个参数是捕获异常的，第一个可以写个`null`或`""`占位

  ```java
  const promise = new Promise((resolve, reject) => {
    // resolve('request success')
    reject('request error')
  })
  
  promise.then(null, rej => console.log(rej))
  
  // 输出内容：request error
  ```

* then`方法是有返回值的，它的返回值是`promise

  ```java
  const promise = new Promise((resolve, reject) => {
    resolve('执行成功')
  })
  
  console.log(promise.then(res => ({name:'张三', age:22})))
   // 返回的是一个Promise对象
  ```

  ![image-20230329100058083](https://trpora-1300527744.cos.ap-chongqing.myqcloud.com/img/202303291000170.png)

  * **返回一个普通值** ***状态:fulfilled***

    ```javascript
    const promise = new Promise((resolve, reject) => {
      resolve('执行成功')
    })
    
    promise.then(res => ({name:'张三', age:22}))
            .then(res => console.log(res))
    // {name: '张三', age: 22}
    ```

    - 返回一个普通值，则相当于主动调用`Promise.resolve`，并且把返回值作为实参传递到`then`方法中。

    - 如果没有返回值，则相当于返回`undefined`

      ```java
      const promise = new Promise((resolve, reject) => {
        resolve('执行成功')
      })
      
      promise.then(res => (console.log(111)))
              .then(res => console.log(res))
      // 111
      // undefined
      ```

  * 明确返回一个promise**状态:fulfilled**
  
    ```java
    const promise = new Promise((resolve, reject) => {
      resolve('执行成功')
    })
    
    promise.then(res => {
      return new Promise((resolve, reject) => {
        resolve('返回的Promise对象resolve里面的内容')
      })
    }).then(res => console.log(res))
    // 返回的Promise对象resolve里面的内容
    ```
  
    **返回一个thenable对象** 状态：fulfilled
  
    ```javascript
    const promise = new Promise((resolve, reject) => {
      resolve('hi ice')
    })
    
    promise.then(res => {
      return {
        then(resolve, reject) {
          resolve('hi webice')
        }
      }
    }).then(res => console.log(res))
    
    //hi webice
    ```

#### catch方法

- 如果返回值明确一个promise或者thenable对象，取决于你调用了`resolve`还是`reject`

   **返回一个普通对象**

  ```javascript
  const promise = new Promise((resolve, reject) => {
    reject('失败')
  })
  
  promise.catch(err => ({name:'张三', age: 22}))
          .then(res => console.log(res)) // 如果这里调用.catch,什么也不会输出
  // {name:'张三', age: 22}
  ```

  **明确返回一个promise**

  ```javascript
  const promise = new Promise((resolve, reject) => {
    reject('ice error')
  })
  
  promise.catch(err => {
    return new Promise((resolve, reject) => {
      reject('ice error promise')
    })
  }).catch(res => console.log(res))
  
  //ice error promise
  ```

  **返回thenable对象**

  ```javascript
  const promise = new Promise((resolve, reject) => {
    reject('ice error')
  })
  
  promise.catch(err => {
    return {
      then(resolve, reject) {
        reject('ice error then')
      }
    }
  }).catch(res => console.log(res))
  
  //ice error then
  ```

#### finally方法

- finally(最后)，无论promise状态是fulfilled还是rejected都会执行一次`finally`方法

### Promise中的类方法/静态方法

#### Promise.reslove/Promise.reject

- 有的时候，你已经预知了状态的结果为fulfilled，则可以用这种简写方式

  ```javascript
  Promise.resolve('abc')
  //等价于
  new Promise((resolve, reject) => resolve('abc'))
  ```

- 有的时候，你已经预知了状态的结果为rejected，则可以用这种简写方式

  ```javascript
  Promise.reject('error')
  //等价于
  new Promise((resolve, reject) => reject('error'))
  ```

#### Promise.all

**fulfilled 状态**

```javascript
const promise1 = new Promise((resolve, reject) => {
  setTimeout(() => {
    resolve('111')
  }, 1000);
})

const promise2 = new Promise((resolve, reject) => {
  setTimeout(() => {
    resolve('222')
  }, 500);
})


Promise.all([promise1, promise2]).then(res => console.log(res))

//[ '111', '222' ]
```

- all方法的参数传入为一个可迭代对象，返回一个promise，只有三个都为`resolve`状态的时候才会调用`.then`方法。
- 只要有一个promise的状态为rejected，则会回调`.catch`方法

**rejected状态**

```javascript
const promise1 = new Promise((resolve, reject) => {
  setTimeout(() => {
    resolve('success1')
  }, 1000);
})

const promise2 = new Promise((resolve, reject) => {
  setTimeout(() => {
    reject('errror1')
  }, 2000);
})

const promise3 = new Promise((resolve, reject) => {
  setTimeout(() => {
    resolve('success2')
  }, 3000);
})

Promise.all([promise1, promise2, promise3]).then(res => console.log(res)).catch(err => console.log(err))

// error1
```

- 当遇到rejectd的时候，后续的promise结果我们是获取不到，并且会把reject的实参，传递给catch的err形参中

> 上面的`Promise.all`有一个缺陷，就是当遇到一个rejected的状态，那么对于后面是`resolve`或者`reject`的结果我们是拿不到的

- ES11 新增语法`Promise.allSettled`，无论状态是fulfilled/rejected都会把参数返回给我们

#### Promise.allSettled

```javascript
const promise1 = new Promise((resolve, reject) => {
  setTimeout(() => {
    resolve('success1')
  }, 1000);
})

const promise2 = new Promise((resolve, reject) => {
  setTimeout(() => {
    reject('errror1')
  }, 500);
})

const promise3 = new Promise((resolve, reject) => {
  setTimeout(() => {
    resolve('success2')
  }, 3000);
})

Promise.allSettled([promise1, promise2, promise3]).then(res => console.log(res)).catch(err => console.log(err))
// [
//     {
//         "status": "fulfilled",
//         "value": "success1"
//     },
//     {
//         "status": "rejected",
//         "reason": "errror1"
//     },
//     {
//         "status": "fulfilled",
//         "value": "success2"
//     }
// ]
```

- 该方法会在所有的Promise都有结果，无论是fulfilled，还是rejected，才会有最终的结果

**其中一个promise没有结果**

```javascript
const promise1 = new Promise((resolve, reject) => {
  setTimeout(() => {
    resolve('success1')
  }, 1000);
})

const promise2 = new Promise((resolve, reject) => {
  setTimeout(() => {
    reject('errror1')
  }, 2000);
})

const promise3 = new Promise((resolve, reject) => {
})

Promise.allSettled([promise1, promise2, promise3]).then(res => console.log(res)).catch(err => console.log(err))
// 什么也不打印
```

#### Promise.race

- race(竞争竞赛)
- 优先获取第一个返回的结果，无论结果是fulfilled还是rejectd

```javascript
const promise1 = new Promise((resolve, reject) => {
  setTimeout(() => {
    reject('error1')
  }, 1000);
})

const promise2 = new Promise((resolve, reject) => {
  setTimeout(() => {
    resolve('success1')
  }, 500);
})


Promise.race([promise1, promise2])
       .then(res => console.log(res))
       .catch(e => console.log(e))
// success1
```

#### Promise.any

- 与race类似，只获取第一个状态为fulfilled，如果全部为rejected则报错`AggregateError`

```javascript
const promise1 = new Promise((resolve, reject) => {
  setTimeout(() => {
    reject('hi error')
  }, 1000);
})

const promise2 = new Promise((resolve, reject) => {
  setTimeout(() => {
    resolve('hi panda')
  }, 2000);
})


Promise.any([promise1, promise2])
       .then(res => console.log(res))
       .catch(e => console.log(e))
       
//hi panda
```

## async/await 

> Promise的语法糖，可以增加代码的可读性（用同步的思维写代码）
>
> await后面的代码都是异步的

- async（异步的）
- async 用于申明一个异步函数

### async内部代码同步执行

- 异步函数的内部代码执行过程和普通的函数是一致的，默认情况下也是会被同步执行

### 异步函数的返回值

- 普通函数主动返回什么就返回什么，不返回为`undefined`

- 异步函数的返回值特点
  - 明确有返回一个普通值，相当于`Promise.resolve`(返回值)
  - 返回一个thenable对象则由，then方法中的`resolve`,或者`reject`有关
  - 明确返回一个promise，则由这个promise决定

### 异步函数的异常处理

- 如果函数内部中途发生错误，可以通过try catch的方式捕获异常
- 如果函数内部中途发生错误，也可以通过函数的返回值.catch进行捕获

```javascript

async function sayHi() {
  console.log(res)
}
sayHi().catch(e => console.log(e))

//或者

async function sayHi() {
  try {
    console.log(res)
  }catch(e) {
    console.log(e)
  }
}

sayHi()

//ReferenceError: res is not defined
```

### await 关键字

- 异步函数中可以使用`await`关键字，普通函数不行
- await特点
  - 通常await关键字后面都是跟一个Promise
    - 可以是普通值
    - 可以是thenable
    - 可以是Promise主动调用`resolve或者reject`
  - 这个promise状态变为fulfilled才会执行`await`后续的代码，所以`await`后面的代码，相当于包括在`.then`方法的回调中，如果状态变为rejected，你则需要在函数内部`try catch`，或者进行链式调用进行`.catch`操作

## 手写Promise加载图片

```javascript
function LoadImg(src){
    return new Promise((resolve, reject) => {
        const Img = new Image();
        Img.src = src;

        Img.onload = () => {
            resolve(Img);
        }

        Img.onerror  = () => {
            reject("图片加载失败");
        }
    });
}
LoadImg('https://robohash.org/1')
    .then((Img) => {
        document.body.appendChild(Img);
        return LoadImg('https://robohash.org/2')
    })
    .then((Img) => {
        document.body.appendChild(Img);
        return LoadImg('https://robohash.org/3')
    })
     .then((Img) => {
        document.body.appendChild(Img);
    })
    .catch((errMsg) => {
        console.log(errMsg);
    })

```

![image-20230328155141667](https://trpora-1300527744.cos.ap-chongqing.myqcloud.com/img/202303281551001.png)

## 参考文章

https://juejin.cn/post/7144308012952322084

Promise阅读代码题：https://juejin.cn/post/6844904077537574919